[2023-03-03T14:32:56.217+0000] {taskinstance.py:1083} INFO - Dependencies all met for <TaskInstance: ETL_dag.transform_data manual__2023-03-03T14:32:54.034092+00:00 [queued]>
[2023-03-03T14:32:56.228+0000] {taskinstance.py:1083} INFO - Dependencies all met for <TaskInstance: ETL_dag.transform_data manual__2023-03-03T14:32:54.034092+00:00 [queued]>
[2023-03-03T14:32:56.229+0000] {taskinstance.py:1279} INFO - 
--------------------------------------------------------------------------------
[2023-03-03T14:32:56.229+0000] {taskinstance.py:1280} INFO - Starting attempt 1 of 2
[2023-03-03T14:32:56.229+0000] {taskinstance.py:1281} INFO - 
--------------------------------------------------------------------------------
[2023-03-03T14:32:56.243+0000] {taskinstance.py:1300} INFO - Executing <Task(PythonOperator): transform_data> on 2023-03-03 14:32:54.034092+00:00
[2023-03-03T14:32:56.250+0000] {standard_task_runner.py:55} INFO - Started process 6768 to run task
[2023-03-03T14:32:56.253+0000] {standard_task_runner.py:82} INFO - Running: ['***', 'tasks', 'run', 'ETL_dag', 'transform_data', 'manual__2023-03-03T14:32:54.034092+00:00', '--job-id', '24', '--raw', '--subdir', 'DAGS_FOLDER/ETL_dag.py', '--cfg-path', '/tmp/tmp6n__dqx4']
[2023-03-03T14:32:56.255+0000] {standard_task_runner.py:83} INFO - Job 24: Subtask transform_data
[2023-03-03T14:32:56.328+0000] {task_command.py:388} INFO - Running <TaskInstance: ETL_dag.transform_data manual__2023-03-03T14:32:54.034092+00:00 [running]> on host bb703684ec8f
[2023-03-03T14:32:56.444+0000] {taskinstance.py:1509} INFO - Exporting the following env vars:
AIRFLOW_CTX_DAG_OWNER=Airflow
AIRFLOW_CTX_DAG_ID=ETL_dag
AIRFLOW_CTX_TASK_ID=transform_data
AIRFLOW_CTX_EXECUTION_DATE=2023-03-03T14:32:54.034092+00:00
AIRFLOW_CTX_TRY_NUMBER=1
AIRFLOW_CTX_DAG_RUN_ID=manual__2023-03-03T14:32:54.034092+00:00
[2023-03-03T14:32:56.466+0000] {taskinstance.py:1768} ERROR - Task failed with exception
Traceback (most recent call last):
  File "/home/airflow/.local/lib/python3.7/site-packages/airflow/operators/python.py", line 175, in execute
    return_value = self.execute_callable()
  File "/home/airflow/.local/lib/python3.7/site-packages/airflow/operators/python.py", line 192, in execute_callable
    return self.python_callable(*self.op_args, **self.op_kwargs)
  File "/opt/airflow/dags/ETL_dag.py", line 22, in _process_data
    df = pd.DataFrame.from_dict(json.loads(json.dumps(data['data'])))
TypeError: 'NoneType' object is not subscriptable
[2023-03-03T14:32:56.480+0000] {taskinstance.py:1323} INFO - Marking task as UP_FOR_RETRY. dag_id=ETL_dag, task_id=transform_data, execution_date=20230303T143254, start_date=20230303T143256, end_date=20230303T143256
[2023-03-03T14:32:56.502+0000] {standard_task_runner.py:105} ERROR - Failed to execute job 24 for task transform_data ('NoneType' object is not subscriptable; 6768)
[2023-03-03T14:32:56.595+0000] {local_task_job.py:208} INFO - Task exited with return code 1
[2023-03-03T14:32:56.625+0000] {taskinstance.py:2578} INFO - 0 downstream tasks scheduled from follow-on schedule check
